
<robot name="mycar">

    <link name="base_link">
        <visual>
            <geometry>
                <box size="0.5 0.3 0.2" />
            </geometry>
            <origin xyz="0 0 0" rpy="0 0 0" />
            <material name="car_color">
                <color rgba="0 0 1 0.5" />
            </material>
        </visual>
    </link>

    <link name="camera">
        <visual>
            <geometry>
                <box size="0.05 0.03 0.02" />
            </geometry>

            <origin xyz="0 0 0.1" rpy="0 0 0" />
            <material name="camera_color">
                <color rgba="0 1 0 1" />
            </material>
        </visual>
    </link>

    <joint name="camera2base" type="continuous">

        <parent link="base_link" />

        <child link="camera" />

        <origin xyz="0.22 0 0.1" rpy="0 0 0" />

        <axis xyz="0 0 1" />
    </joint>
</robot>